2025-08-20 15:53:25,535 - ERROR - Infinity polling exception: HTTPSConnectionPool(host='api.telegram.org', port=443): Read timed out. (read timeout=25)
2025-08-20 15:53:25,543 - ERROR - Exception traceback:
Traceback (most recent call last):
  File "C:\Users\User\AppData\Roaming\Python\Python313\site-packages\urllib3\connectionpool.py", line 534, in _make_request
    response = conn.getresponse()
  File "C:\Users\User\AppData\Roaming\Python\Python313\site-packages\urllib3\connection.py", line 565, in getresponse
    httplib_response = super().getresponse()
  File "C:\Program Files\Python313\Lib\http\client.py", line 1430, in getresponse
    response.begin()
    ~~~~~~~~~~~~~~^^
  File "C:\Program Files\Python313\Lib\http\client.py", line 331, in begin
    version, status, reason = self._read_status()
                              ~~~~~~~~~~~~~~~~~^^
  File "C:\Program Files\Python313\Lib\http\client.py", line 292, in _read_status
    line = str(self.fp.readline(_MAXLINE + 1), "iso-8859-1")
               ~~~~~~~~~~~~~~~~^^^^^^^^^^^^^^
  File "C:\Program Files\Python313\Lib\socket.py", line 719, in readinto
    return self._sock.recv_into(b)
           ~~~~~~~~~~~~~~~~~~~~^^^
  File "C:\Program Files\Python313\Lib\ssl.py", line 1304, in recv_into
    return self.read(nbytes, buffer)
           ~~~~~~~~~^^^^^^^^^^^^^^^^
  File "C:\Program Files\Python313\Lib\ssl.py", line 1138, in read
    return self._sslobj.read(len, buffer)
           ~~~~~~~~~~~~~~~~~^^^^^^^^^^^^^
TimeoutError: The read operation timed out

The above exception was the direct cause of the following exception:

Traceback (most recent call last):
  File "C:\Users\User\AppData\Roaming\Python\Python313\site-packages\requests\adapters.py", line 644, in send
    resp = conn.urlopen(
        method=request.method,
    ...<9 lines>...
        chunked=chunked,
    )
  File "C:\Users\User\AppData\Roaming\Python\Python313\site-packages\urllib3\connectionpool.py", line 841, in urlopen
    retries = retries.increment(
        method, url, error=new_e, _pool=self, _stacktrace=sys.exc_info()[2]
    )
  File "C:\Users\User\AppData\Roaming\Python\Python313\site-packages\urllib3\util\retry.py", line 474, in increment
    raise reraise(type(error), error, _stacktrace)
          ~~~~~~~^^^^^^^^^^^^^^^^^^^^^^^^^^^^^^^^^
  File "C:\Users\User\AppData\Roaming\Python\Python313\site-packages\urllib3\util\util.py", line 39, in reraise
    raise value
  File "C:\Users\User\AppData\Roaming\Python\Python313\site-packages\urllib3\connectionpool.py", line 787, in urlopen
    response = self._make_request(
        conn,
    ...<10 lines>...
        **response_kw,
    )
  File "C:\Users\User\AppData\Roaming\Python\Python313\site-packages\urllib3\connectionpool.py", line 536, in _make_request
    self._raise_timeout(err=e, url=url, timeout_value=read_timeout)
    ~~~~~~~~~~~~~~~~~~~^^^^^^^^^^^^^^^^^^^^^^^^^^^^^^^^^^^^^^^^^^^^
  File "C:\Users\User\AppData\Roaming\Python\Python313\site-packages\urllib3\connectionpool.py", line 367, in _raise_timeout
    raise ReadTimeoutError(
        self, url, f"Read timed out. (read timeout={timeout_value})"
    ) from err
urllib3.exceptions.ReadTimeoutError: HTTPSConnectionPool(host='api.telegram.org', port=443): Read timed out. (read timeout=25)

During handling of the above exception, another exception occurred:

Traceback (most recent call last):
  File "C:\Users\User\AppData\Roaming\Python\Python313\site-packages\telebot\__init__.py", line 1110, in infinity_polling
    self.polling(non_stop=True, timeout=timeout, long_polling_timeout=long_polling_timeout,
    ~~~~~~~~~~~~^^^^^^^^^^^^^^^^^^^^^^^^^^^^^^^^^^^^^^^^^^^^^^^^^^^^^^^^^^^^^^^^^^^^^^^^^^^
                 logger_level=logger_level, allowed_updates=allowed_updates, restart_on_change=False,
                 ^^^^^^^^^^^^^^^^^^^^^^^^^^^^^^^^^^^^^^^^^^^^^^^^^^^^^^^^^^^^^^^^^^^^^^^^^^^^^^^^^^^^
                 *args, **kwargs)
                 ^^^^^^^^^^^^^^^^
  File "C:\Users\User\AppData\Roaming\Python\Python313\site-packages\telebot\__init__.py", line 1198, in polling
    self.__threaded_polling(non_stop=non_stop, interval=interval, timeout=timeout, long_polling_timeout=long_polling_timeout,
    ~~~~~~~~~~~~~~~~~~~~~~~^^^^^^^^^^^^^^^^^^^^^^^^^^^^^^^^^^^^^^^^^^^^^^^^^^^^^^^^^^^^^^^^^^^^^^^^^^^^^^^^^^^^^^^^^^^^^^^^^^
                            logger_level=logger_level, allowed_updates=allowed_updates)
                            ^^^^^^^^^^^^^^^^^^^^^^^^^^^^^^^^^^^^^^^^^^^^^^^^^^^^^^^^^^^
  File "C:\Users\User\AppData\Roaming\Python\Python313\site-packages\telebot\__init__.py", line 1273, in __threaded_polling
    raise e
  File "C:\Users\User\AppData\Roaming\Python\Python313\site-packages\telebot\__init__.py", line 1234, in __threaded_polling
    polling_thread.raise_exceptions()
    ~~~~~~~~~~~~~~~~~~~~~~~~~~~~~~~^^
  File "C:\Users\User\AppData\Roaming\Python\Python313\site-packages\telebot\util.py", line 112, in raise_exceptions
    raise self.exception_info
  File "C:\Users\User\AppData\Roaming\Python\Python313\site-packages\telebot\util.py", line 94, in run
    task(*args, **kwargs)
    ~~~~^^^^^^^^^^^^^^^^^
  File "C:\Users\User\AppData\Roaming\Python\Python313\site-packages\telebot\__init__.py", line 688, in __retrieve_updates
    updates = self.get_updates(offset=(self.last_update_id + 1),
                               allowed_updates=allowed_updates,
                               timeout=timeout, long_polling_timeout=long_polling_timeout)
  File "C:\Users\User\AppData\Roaming\Python\Python313\site-packages\telebot\__init__.py", line 660, in get_updates
    json_updates = apihelper.get_updates(
        self.token, offset=offset, limit=limit, timeout=timeout, allowed_updates=allowed_updates,
        long_polling_timeout=long_polling_timeout)
  File "C:\Users\User\AppData\Roaming\Python\Python313\site-packages\telebot\apihelper.py", line 332, in get_updates
    return _make_request(token, method_url, params=payload)
  File "C:\Users\User\AppData\Roaming\Python\Python313\site-packages\telebot\apihelper.py", line 162, in _make_request
    result = _get_req_session().request(
        method, request_url, params=params, files=files,
        timeout=(connect_timeout, read_timeout), proxies=proxy)
  File "C:\Users\User\AppData\Roaming\Python\Python313\site-packages\requests\sessions.py", line 589, in request
    resp = self.send(prep, **send_kwargs)
  File "C:\Users\User\AppData\Roaming\Python\Python313\site-packages\requests\sessions.py", line 703, in send
    r = adapter.send(request, **kwargs)
  File "C:\Users\User\AppData\Roaming\Python\Python313\site-packages\requests\adapters.py", line 690, in send
    raise ReadTimeout(e, request=request)
requests.exceptions.ReadTimeout: HTTPSConnectionPool(host='api.telegram.org', port=443): Read timed out. (read timeout=25)

2025-08-20 15:55:01,832 - WARNING - Чат 6547700059 недоступен: A request to the Telegram API was unsuccessful. Error code: 403. Description: Forbidden: bot was blocked by the user
2025-08-20 15:55:01,978 - INFO - Удалены заблокированные чаты: {6547700059}
2025-08-20 15:56:35,883 - ERROR - Infinity polling: polling exited
2025-08-20 15:56:35,884 - ERROR - Break infinity polling
2025-08-20 15:57:00,977 - WARNING - Чат 759673350 недоступен: A request to the Telegram API was unsuccessful. Error code: 403. Description: Forbidden: bot was blocked by the user
2025-08-20 15:57:41,756 - ERROR - Infinity polling: polling exited
2025-08-20 15:57:41,757 - ERROR - Break infinity polling
